Traceback (most recent call last):
  File "c:\users\dudas\anaconda3\envs\wintest\lib\site-packages\jupyter_cache\executors\utils.py", line 56, in single_nb_execution
    record_timing=False,
  File "c:\users\dudas\anaconda3\envs\wintest\lib\site-packages\nbclient\client.py", line 1112, in execute
    return NotebookClient(nb=nb, resources=resources, km=km, **kwargs).execute()
  File "c:\users\dudas\anaconda3\envs\wintest\lib\site-packages\nbclient\util.py", line 74, in wrapped
    return just_run(coro(*args, **kwargs))
  File "c:\users\dudas\anaconda3\envs\wintest\lib\site-packages\nbclient\util.py", line 53, in just_run
    return loop.run_until_complete(coro)
  File "c:\users\dudas\anaconda3\envs\wintest\lib\asyncio\base_events.py", line 587, in run_until_complete
    return future.result()
  File "c:\users\dudas\anaconda3\envs\wintest\lib\site-packages\nbclient\client.py", line 554, in async_execute
    cell, index, execution_count=self.code_cells_executed + 1
  File "c:\users\dudas\anaconda3\envs\wintest\lib\site-packages\nbclient\client.py", line 857, in async_execute_cell
    self._check_raise_for_error(cell, exec_reply)
  File "c:\users\dudas\anaconda3\envs\wintest\lib\site-packages\nbclient\client.py", line 760, in _check_raise_for_error
    raise CellExecutionError.from_cell_and_msg(cell, exec_reply_content)
nbclient.exceptions.CellExecutionError: An error occurred while executing the following cell:
------------------
import requests
import json
url = r'http://ogre.adc4gis.com/convert'
f = open('cb_2018_us_county_20m.zip', "rb")
shp_data = {'upload': f}
print('Calling Ogre to perform shapefile to geoJSON conversion...')
try: 
    r = requests.post(url, files=shp_data)
except:
    print("There was an error with the HTTP request")
    raise
r.raise_for_status()
# close the new file 
f.close()
with open("cb_2018_us_county_20m.json", 'w') as f: 
    f.write(json.dumps(r.json(),separators=(',', ':')))
print("File is ready, called: cb_2018_us_county_20m.json")
------------------

[1;31m---------------------------------------------------------------------------[0m
[1;31mHTTPError[0m                                 Traceback (most recent call last)
[1;32m<ipython-input-3-2c705cc29c01>[0m in [0;36m<module>[1;34m[0m
[0;32m     10[0m     [0mprint[0m[1;33m([0m[1;34m"There was an error with the HTTP request"[0m[1;33m)[0m[1;33m[0m[1;33m[0m[0m
[0;32m     11[0m     [1;32mraise[0m[1;33m[0m[1;33m[0m[0m
[1;32m---> 12[1;33m [0mr[0m[1;33m.[0m[0mraise_for_status[0m[1;33m([0m[1;33m)[0m[1;33m[0m[1;33m[0m[0m
[0m[0;32m     13[0m [1;31m# close the new file[0m[1;33m[0m[1;33m[0m[1;33m[0m[0m
[0;32m     14[0m [0mf[0m[1;33m.[0m[0mclose[0m[1;33m([0m[1;33m)[0m[1;33m[0m[1;33m[0m[0m

[1;32mc:\users\dudas\anaconda3\envs\wintest\lib\site-packages\requests\models.py[0m in [0;36mraise_for_status[1;34m(self)[0m
[0;32m    941[0m [1;33m[0m[0m
[0;32m    942[0m         [1;32mif[0m [0mhttp_error_msg[0m[1;33m:[0m[1;33m[0m[1;33m[0m[0m
[1;32m--> 943[1;33m             [1;32mraise[0m [0mHTTPError[0m[1;33m([0m[0mhttp_error_msg[0m[1;33m,[0m [0mresponse[0m[1;33m=[0m[0mself[0m[1;33m)[0m[1;33m[0m[1;33m[0m[0m
[0m[0;32m    944[0m [1;33m[0m[0m
[0;32m    945[0m     [1;32mdef[0m [0mclose[0m[1;33m([0m[0mself[0m[1;33m)[0m[1;33m:[0m[1;33m[0m[1;33m[0m[0m

[1;31mHTTPError[0m: 500 Server Error: Internal Server Error for url: http://ogre.adc4gis.com/convert
HTTPError: 500 Server Error: Internal Server Error for url: http://ogre.adc4gis.com/convert

